<?xml version="1.0" ?>
<!-- =================================================================================== -->
<!-- |    This document was autogenerated by xacro from simple7sky.xacro               | -->
<!-- |    EDITING THIS FILE BY HAND IS NOT RECOMMENDED                                 | -->
<!-- =================================================================================== -->
<robot name="simple7sky">
  <link name="base_link">
    <inertial>
      <origin rpy="0 0 0" xyz="6.16526679736714e-15 5.050387435335943e-06 0.06094638477109512"/>
      <mass value="18.250474833074623"/>
      <inertia ixx="0.085361" ixy="0.0" ixz="0.0" iyy="0.108511" iyz="5e-06" izz="0.096599"/>
    </inertial>
    <visual>
      <origin rpy="0 0 0" xyz="0 0 0"/>
      <geometry>
        <mesh filename="meshes_simple7sky/base_link.stl" scale="0.001 0.001 0.001"/>
      </geometry>
      <material name="silver"/>
    </visual>
    <collision>
      <origin rpy="0 0 0" xyz="0 0 0"/>
      <geometry>
        <mesh filename="meshes_simple7sky/base_link.stl" scale="0.001 0.001 0.001"/>
      </geometry>
    </collision>
  </link>
  <link name="jHor_1">
    <inertial>
      <origin rpy="0 0 0" xyz="-4.8107555643006375e-12 -0.002612981250012781 0.06374127790658082"/>
      <mass value="5.564807768189837"/>
      <inertia ixx="0.009595" ixy="0.0" ixz="-0.0" iyy="0.006139" iyz="0.000184" izz="0.008949"/>
    </inertial>
    <visual>
      <origin rpy="0 0 0" xyz="-0.0 0.0 -0.172"/>
      <geometry>
        <mesh filename="meshes_simple7sky/jHor_1.stl" scale="0.001 0.001 0.001"/>
      </geometry>
      <material name="silver"/>
    </visual>
    <collision>
      <origin rpy="0 0 0" xyz="-0.0 0.0 -0.172"/>
      <geometry>
        <mesh filename="meshes_simple7sky/jHor_1.stl" scale="0.001 0.001 0.001"/>
      </geometry>
    </collision>
  </link>
  <link name="jVert_1">
    <inertial>
      <origin rpy="0 0 0" xyz="-6.0049164284592393e-05 -0.04561655987937348 0.1586778161452157"/>
      <mass value="6.178248990841839"/>
      <inertia ixx="0.018277" ixy="-3e-06" ixz="4e-06" iyy="0.016375" iyz="0.002854" izz="0.007856"/>
    </inertial>
    <visual>
      <origin rpy="0 0 0" xyz="-0.0 -0.0546 -0.23846"/>
      <geometry>
        <mesh filename="meshes_simple7sky/jVert_1.stl" scale="0.001 0.001 0.001"/>
      </geometry>
      <material name="silver"/>
    </visual>
    <collision>
      <origin rpy="0 0 0" xyz="-0.0 -0.0546 -0.23846"/>
      <geometry>
        <mesh filename="meshes_simple7sky/jVert_1.stl" scale="0.001 0.001 0.001"/>
      </geometry>
    </collision>
  </link>
  <link name="jHor_2">
    <inertial>
      <origin rpy="0 0 0" xyz="-2.840068382461294e-06 -0.0026129392168440235 0.06374088361947128"/>
      <mass value="5.564807768189837"/>
      <inertia ixx="0.009595" ixy="-4e-06" ixz="0.0" iyy="0.006139" iyz="0.000184" izz="0.008949"/>
    </inertial>
    <visual>
      <origin rpy="0 0 0" xyz="7e-05 -0.0011 -0.46446"/>
      <geometry>
        <mesh filename="meshes_simple7sky/jHor_2.stl" scale="0.001 0.001 0.001"/>
      </geometry>
      <material name="silver"/>
    </visual>
    <collision>
      <origin rpy="0 0 0" xyz="7e-05 -0.0011 -0.46446"/>
      <geometry>
        <mesh filename="meshes_simple7sky/jHor_2.stl" scale="0.001 0.001 0.001"/>
      </geometry>
    </collision>
  </link>
  <link name="jVert_2">
    <inertial>
      <origin rpy="0 0 0" xyz="-0.00011250550588334606 -0.045616456265365965 0.1586784218581061"/>
      <mass value="6.178248990841839"/>
      <inertia ixx="0.018277" ixy="-5e-06" ixz="7e-06" iyy="0.016375" iyz="0.002854" izz="0.007856"/>
    </inertial>
    <visual>
      <origin rpy="0 0 0" xyz="7e-06 -0.0557 -0.530919"/>
      <geometry>
        <mesh filename="meshes_simple7sky/jVert_2.stl" scale="0.001 0.001 0.001"/>
      </geometry>
      <material name="silver"/>
    </visual>
    <collision>
      <origin rpy="0 0 0" xyz="7e-06 -0.0557 -0.530919"/>
      <geometry>
        <mesh filename="meshes_simple7sky/jVert_2.stl" scale="0.001 0.001 0.001"/>
      </geometry>
    </collision>
  </link>
  <link name="jHor_3">
    <inertial>
      <origin rpy="0 0 0" xyz="-6.410501020342579e-06 -0.002612813850000863 0.06374148933236179"/>
      <mass value="5.564807768189837"/>
      <inertia ixx="0.009595" ixy="-8e-06" ixz="0.0" iyy="0.006139" iyz="0.000184" izz="0.008949"/>
    </inertial>
    <visual>
      <origin rpy="0 0 0" xyz="0.000138 -0.0022 -0.756919"/>
      <geometry>
        <mesh filename="meshes_simple7sky/jHor_3.stl" scale="0.001 0.001 0.001"/>
      </geometry>
      <material name="silver"/>
    </visual>
    <collision>
      <origin rpy="0 0 0" xyz="0.000138 -0.0022 -0.756919"/>
      <geometry>
        <mesh filename="meshes_simple7sky/jHor_3.stl" scale="0.001 0.001 0.001"/>
      </geometry>
    </collision>
  </link>
  <link name="joint7_1">
    <inertial>
      <origin rpy="0 0 0" xyz="-0.000150609344771667 -0.04097073665289449 0.16118762381583218"/>
      <mass value="6.5348381432276215"/>
      <inertia ixx="0.021508" ixy="-1.4e-05" ixz="6e-06" iyy="0.017368" iyz="0.00151" izz="0.010579"/>
    </inertial>
    <visual>
      <origin rpy="0 0 0" xyz="1.2e-05 -0.0568 -0.823379"/>
      <geometry>
        <mesh filename="meshes_simple7sky/joint7_1.stl" scale="0.001 0.001 0.001"/>
      </geometry>
      <material name="silver"/>
    </visual>
    <collision>
      <origin rpy="0 0 0" xyz="1.2e-05 -0.0568 -0.823379"/>
      <geometry>
        <mesh filename="meshes_simple7sky/joint7_1.stl" scale="0.001 0.001 0.001"/>
      </geometry>
    </collision>
  </link>
  <link name="tool_1">
    <inertial>
      <origin rpy="0 0 0" xyz="-1.4920958159815947e-05 -0.004409125625040424 0.009807477265531439"/>
      <mass value="0.038676053324605233"/>
      <inertia ixx="2.8e-05" ixy="-0.0" ixz="0.0" iyy="2.6e-05" iyz="2e-06" izz="3e-06"/>
    </inertial>
    <visual>
      <origin rpy="0 0 0" xyz="0.000206 -0.0033 -1.049379"/>
      <geometry>
        <mesh filename="meshes_simple7sky/tool_1.stl" scale="0.001 0.001 0.001"/>
      </geometry>
      <material name="silver"/>
    </visual>
    <collision>
      <origin rpy="0 0 0" xyz="0.000206 -0.0033 -1.049379"/>
      <geometry>
        <mesh filename="meshes_simple7sky/tool_1.stl" scale="0.001 0.001 0.001"/>
      </geometry>
    </collision>
  </link>
  <joint name="obr1" type="revolute">
    <origin rpy="0 0 0" xyz="0.0 0.0 0.172"/>
    <parent link="base_link"/>
    <child link="jHor_1"/>
    <axis xyz="0.0 0.0 -1.0"/>
    <limit lower="-3.14" upper="3.14" effort="180.0" velocity="1.0"/>
  </joint>
  <joint name="obr2" type="revolute">
    <origin rpy="0 0 0" xyz="0.0 0.0546 0.06646"/>
    <parent link="jHor_1"/>
    <child link="jVert_1"/>
    <axis xyz="0.0 -1.0 0.0"/>
    <limit lower="-3.14" upper="3.14" effort="180.0" velocity="1.0"/>
  </joint>
  <joint name="obr3" type="revolute">
    <origin rpy="0 0 0" xyz="-7e-05 -0.0535 0.226"/>
    <parent link="jVert_1"/>
    <child link="jHor_2"/>
    <axis xyz="-0.0 -0.0 -1.0"/>
    <limit lower="-3.14" upper="3.14" effort="180.0" velocity="1.0"/>
  </joint>
  <joint name="obr4" type="revolute">
    <origin rpy="0 0 0" xyz="6.3e-05 0.0546 0.066459"/>
    <parent link="jHor_2"/>
    <child link="jVert_2"/>
    <axis xyz="-0.001154 -0.999999 0.0"/>
    <limit lower="-3.14" upper="3.14" effort="180.0" velocity="1.0"/>
  </joint>
  <joint name="obr5" type="revolute">
    <origin rpy="0 0 0" xyz="-0.000131 -0.0535 0.226"/>
    <parent link="jVert_2"/>
    <child link="jHor_3"/>
    <axis xyz="-0.0 -0.0 -1.0"/>
    <limit lower="-3.14" upper="3.14" effort="180.0" velocity="1.0"/>
  </joint>
  <joint name="obr6" type="revolute">
    <origin rpy="0 0 0" xyz="0.000126 0.0546 0.06646"/>
    <parent link="jHor_3"/>
    <child link="joint7_1"/>
    <axis xyz="-0.002308 -0.999997 0.0"/>
    <limit lower="-3.14" upper="3.14" effort="180.0" velocity="1.0"/>
  </joint>
  <joint name="obr7" type="revolute">
    <origin rpy="0 0 0" xyz="-0.000194 -0.0535 0.226"/>
    <parent link="joint7_1"/>
    <child link="tool_1"/>
    <axis xyz="-0.0 -0.0 -1.0"/>
    <limit lower="-3.14" upper="3.14" effort="180.0" velocity="1.0"/>
  </joint>
</robot>
