<?xml version="1.0" ?>
<!-- =================================================================================== -->
<!-- |    This document was autogenerated by xacro from sky7.xacro                     | -->
<!-- |    EDITING THIS FILE BY HAND IS NOT RECOMMENDED                                 | -->
<!-- =================================================================================== -->
<robot name="sky7">
  <link name="base_link">
    <inertial>
      <origin rpy="0 0 0" xyz="-1.6113547694874978e-15 1.8940913138634485e-05 0.0064626899691258245"/>
      <mass value="5.937224346313427"/>
      <inertia ixx="0.018869" ixy="-0.0" ixz="-0.0" iyy="0.042016" iyz="0.0" izz="0.060709"/>
    </inertial>
    <visual>
      <origin rpy="0 0 0" xyz="0 0 0"/>
      <geometry>
        <mesh filename="meshes_7sky/base_link.stl" scale="0.001 0.001 0.001"/>
      </geometry>
      <material name="silver"/>
    </visual>
    <collision>
      <origin rpy="0 0 0" xyz="0 0 0"/>
      <geometry>
        <mesh filename="meshes_7sky/base_link.stl" scale="0.001 0.001 0.001"/>
      </geometry>
    </collision>
  </link>
  <link name="cover1_1">
    <inertial>
      <origin rpy="0 0 0" xyz="-1.3417786171718322e-07 -2.529519138261787e-06 0.05522564657205477"/>
      <mass value="7.0497176951642775"/>
      <inertia ixx="0.025188" ixy="-0.0" ixz="-0.0" iyy="0.02519" iyz="-1e-06" izz="0.030801"/>
    </inertial>
    <visual>
      <origin rpy="0 0 0" xyz="-0.0 -0.0 -0.012"/>
      <geometry>
        <mesh filename="meshes_7sky/cover1_1.stl" scale="0.001 0.001 0.001"/>
      </geometry>
      <material name="silver"/>
    </visual>
    <collision>
      <origin rpy="0 0 0" xyz="-0.0 -0.0 -0.012"/>
      <geometry>
        <mesh filename="meshes_7sky/cover1_1.stl" scale="0.001 0.001 0.001"/>
      </geometry>
    </collision>
  </link>
  <link name="J1_1">
    <inertial>
      <origin rpy="0 0 0" xyz="-1.2049633286800674e-05 -0.047998877876147115 -0.027936819480223737"/>
      <mass value="3.4591697822080767"/>
      <inertia ixx="0.006219" ixy="1e-06" ixz="1e-06" iyy="0.006222" iyz="3e-06" izz="0.003734"/>
    </inertial>
    <visual>
      <origin rpy="0 0 0" xyz="0.0 -0.048 -0.136"/>
      <geometry>
        <mesh filename="meshes_7sky/J1_1.stl" scale="0.001 0.001 0.001"/>
      </geometry>
      <material name="silver"/>
    </visual>
    <collision>
      <origin rpy="0 0 0" xyz="0.0 -0.048 -0.136"/>
      <geometry>
        <mesh filename="meshes_7sky/J1_1.stl" scale="0.001 0.001 0.001"/>
      </geometry>
    </collision>
  </link>
  <link name="L1_1">
    <inertial>
      <origin rpy="0 0 0" xyz="-8.980076944736388e-11 0.012329382318895035 0.0157402936137076"/>
      <mass value="0.29834763022982164"/>
      <inertia ixx="0.000175" ixy="0.0" ixz="-0.0" iyy="0.000313" iyz="-4.2e-05" izz="0.000255"/>
    </inertial>
    <visual>
      <origin rpy="0 0 0" xyz="0.0 -0.0 -0.172"/>
      <geometry>
        <mesh filename="meshes_7sky/L1_1.stl" scale="0.001 0.001 0.001"/>
      </geometry>
      <material name="silver"/>
    </visual>
    <collision>
      <origin rpy="0 0 0" xyz="0.0 -0.0 -0.172"/>
      <geometry>
        <mesh filename="meshes_7sky/L1_1.stl" scale="0.001 0.001 0.001"/>
      </geometry>
    </collision>
  </link>
  <link name="J2_1">
    <inertial>
      <origin rpy="0 0 0" xyz="-1.2049633286800646e-05 -0.027936819480223838 0.04799848358903766"/>
      <mass value="3.4591697822080767"/>
      <inertia ixx="0.006219" ixy="1e-06" ixz="-1e-06" iyy="0.003734" iyz="-3e-06" izz="0.006222"/>
    </inertial>
    <visual>
      <origin rpy="0 0 0" xyz="0.0 -0.0186 -0.19046"/>
      <geometry>
        <mesh filename="meshes_7sky/J2_1.stl" scale="0.001 0.001 0.001"/>
      </geometry>
      <material name="silver"/>
    </visual>
    <collision>
      <origin rpy="0 0 0" xyz="0.0 -0.0186 -0.19046"/>
      <geometry>
        <mesh filename="meshes_7sky/J2_1.stl" scale="0.001 0.001 0.001"/>
      </geometry>
    </collision>
  </link>
  <link name="L2_1">
    <inertial>
      <origin rpy="0 0 0" xyz="-3.5816026978797294e-06 -7.682149769773494e-05 0.10517900764274013"/>
      <mass value="0.9117888535967525"/>
      <inertia ixx="0.004373" ixy="0.0" ixz="0.0" iyy="0.00469" iyz="0.000248" izz="0.000538"/>
    </inertial>
    <visual>
      <origin rpy="0 0 0" xyz="0.0 -0.0546 -0.23846"/>
      <geometry>
        <mesh filename="meshes_7sky/L2_1.stl" scale="0.001 0.001 0.001"/>
      </geometry>
      <material name="silver"/>
    </visual>
    <collision>
      <origin rpy="0 0 0" xyz="0.0 -0.0546 -0.23846"/>
      <geometry>
        <mesh filename="meshes_7sky/L2_1.stl" scale="0.001 0.001 0.001"/>
      </geometry>
    </collision>
  </link>
  <link name="J3_1">
    <inertial>
      <origin rpy="0 0 0" xyz="-6.78726953126909e-05 -0.04799882367723014 -0.027937213767333435"/>
      <mass value="3.4591697822080767"/>
      <inertia ixx="0.006219" ixy="1e-06" ixz="1e-06" iyy="0.006222" iyz="3e-06" izz="0.003734"/>
    </inertial>
    <visual>
      <origin rpy="0 0 0" xyz="1.4e-05 -0.0491 -0.42846"/>
      <geometry>
        <mesh filename="meshes_7sky/J3_1.stl" scale="0.001 0.001 0.001"/>
      </geometry>
      <material name="silver"/>
    </visual>
    <collision>
      <origin rpy="0 0 0" xyz="1.4e-05 -0.0491 -0.42846"/>
      <geometry>
        <mesh filename="meshes_7sky/J3_1.stl" scale="0.001 0.001 0.001"/>
      </geometry>
    </collision>
  </link>
  <link name="L3_1">
    <inertial>
      <origin rpy="0 0 0" xyz="1.4405153224256927e-05 0.012329414400566665 0.015739899326597917"/>
      <mass value="0.29834763022982164"/>
      <inertia ixx="0.000175" ixy="0.0" ixz="-0.0" iyy="0.000313" iyz="-4.2e-05" izz="0.000255"/>
    </inertial>
    <visual>
      <origin rpy="0 0 0" xyz="7e-05 -0.0011 -0.46446"/>
      <geometry>
        <mesh filename="meshes_7sky/L3_1.stl" scale="0.001 0.001 0.001"/>
      </geometry>
      <material name="silver"/>
    </visual>
    <collision>
      <origin rpy="0 0 0" xyz="7e-05 -0.0011 -0.46446"/>
      <geometry>
        <mesh filename="meshes_7sky/L3_1.stl" scale="0.001 0.001 0.001"/>
      </geometry>
    </collision>
  </link>
  <link name="J4_1">
    <inertial>
      <origin rpy="0 0 0" xyz="-4.464981670088769e-05 -0.027936759062249628 0.04799908930192809"/>
      <mass value="3.4591697822080767"/>
      <inertia ixx="0.006219" ixy="-1e-06" ixz="-1e-06" iyy="0.003734" iyz="-3e-06" izz="0.006222"/>
    </inertial>
    <visual>
      <origin rpy="0 0 0" xyz="4.8e-05 -0.0197 -0.482919"/>
      <geometry>
        <mesh filename="meshes_7sky/J4_1.stl" scale="0.001 0.001 0.001"/>
      </geometry>
      <material name="silver"/>
    </visual>
    <collision>
      <origin rpy="0 0 0" xyz="4.8e-05 -0.0197 -0.482919"/>
      <geometry>
        <mesh filename="meshes_7sky/J4_1.stl" scale="0.001 0.001 0.001"/>
      </geometry>
    </collision>
  </link>
  <link name="L4_1">
    <inertial>
      <origin rpy="0 0 0" xyz="-3.4795799272473788e-06 -7.681338353822398e-05 0.10517961335563053"/>
      <mass value="0.9117888535967525"/>
      <inertia ixx="0.004373" ixy="0.0" ixz="1e-06" iyy="0.00469" iyz="0.000248" izz="0.000538"/>
    </inertial>
    <visual>
      <origin rpy="0 0 0" xyz="7e-06 -0.0557 -0.530919"/>
      <geometry>
        <mesh filename="meshes_7sky/L4_1.stl" scale="0.001 0.001 0.001"/>
      </geometry>
      <material name="silver"/>
    </visual>
    <collision>
      <origin rpy="0 0 0" xyz="7e-06 -0.0557 -0.530919"/>
      <geometry>
        <mesh filename="meshes_7sky/L4_1.stl" scale="0.001 0.001 0.001"/>
      </geometry>
    </collision>
  </link>
  <link name="J5_1">
    <inertial>
      <origin rpy="0 0 0" xyz="-0.0001224261143731809 -0.04799868962663415 -0.02793660805444287"/>
      <mass value="3.4591697822080767"/>
      <inertia ixx="0.006219" ixy="1e-06" ixz="1e-06" iyy="0.006222" iyz="3e-06" izz="0.003734"/>
    </inertial>
    <visual>
      <origin rpy="0 0 0" xyz="2.8e-05 -0.0502 -0.720919"/>
      <geometry>
        <mesh filename="meshes_7sky/J5_1.stl" scale="0.001 0.001 0.001"/>
      </geometry>
      <material name="silver"/>
    </visual>
    <collision>
      <origin rpy="0 0 0" xyz="2.8e-05 -0.0502 -0.720919"/>
      <geometry>
        <mesh filename="meshes_7sky/J5_1.stl" scale="0.001 0.001 0.001"/>
      </geometry>
    </collision>
  </link>
  <link name="L5_1">
    <inertial>
      <origin rpy="0 0 0" xyz="2.8080004212657027e-05 0.012329509912735837 0.015740505039488872"/>
      <mass value="0.29834763022982164"/>
      <inertia ixx="0.000175" ixy="0.0" ixz="-0.0" iyy="0.000313" iyz="-4.2e-05" izz="0.000255"/>
    </inertial>
    <visual>
      <origin rpy="0 0 0" xyz="0.000138 -0.0022 -0.756319"/>
      <geometry>
        <mesh filename="meshes_7sky/L5_1.stl" scale="0.001 0.001 0.001"/>
      </geometry>
      <material name="silver"/>
    </visual>
    <collision>
      <origin rpy="0 0 0" xyz="0.000138 -0.0022 -0.756319"/>
      <geometry>
        <mesh filename="meshes_7sky/L5_1.stl" scale="0.001 0.001 0.001"/>
      </geometry>
    </collision>
  </link>
  <link name="J6_1">
    <inertial>
      <origin rpy="0 0 0" xyz="-7.698034279447625e-05 -0.027936606354490516 0.04799869501481868"/>
      <mass value="3.4591697822080767"/>
      <inertia ixx="0.006219" ixy="-4e-06" ixz="-1e-06" iyy="0.003734" iyz="-3e-06" izz="0.006222"/>
    </inertial>
    <visual>
      <origin rpy="0 0 0" xyz="9.5e-05 -0.0208 -0.774779"/>
      <geometry>
        <mesh filename="meshes_7sky/J6_1.stl" scale="0.001 0.001 0.001"/>
      </geometry>
      <material name="silver"/>
    </visual>
    <collision>
      <origin rpy="0 0 0" xyz="9.5e-05 -0.0208 -0.774779"/>
      <geometry>
        <mesh filename="meshes_7sky/J6_1.stl" scale="0.001 0.001 0.001"/>
      </geometry>
    </collision>
  </link>
  <link name="L6_1">
    <inertial>
      <origin rpy="0 0 0" xyz="-7.047473685844884e-06 -1.5716245417136954e-05 0.10721582346819292"/>
      <mass value="0.9321314472557242"/>
      <inertia ixx="0.004549" ixy="1e-06" ixz="1e-06" iyy="0.004867" iyz="0.000242" izz="0.000544"/>
    </inertial>
    <visual>
      <origin rpy="0 0 0" xyz="1.2e-05 -0.0568 -0.822779"/>
      <geometry>
        <mesh filename="meshes_7sky/L6_1.stl" scale="0.001 0.001 0.001"/>
      </geometry>
      <material name="silver"/>
    </visual>
    <collision>
      <origin rpy="0 0 0" xyz="1.2e-05 -0.0568 -0.822779"/>
      <geometry>
        <mesh filename="meshes_7sky/L6_1.stl" scale="0.001 0.001 0.001"/>
      </geometry>
    </collision>
  </link>
  <link name="J7_1">
    <inertial>
      <origin rpy="0 0 0" xyz="-0.00017870979915529233 -0.04799847718973476 -0.027937002341552053"/>
      <mass value="3.4591697822080767"/>
      <inertia ixx="0.006219" ixy="1e-06" ixz="1e-06" iyy="0.006222" iyz="3e-06" izz="0.003734"/>
    </inertial>
    <visual>
      <origin rpy="0 0 0" xyz="3.9e-05 -0.0513 -1.012779"/>
      <geometry>
        <mesh filename="meshes_7sky/J7_1.stl" scale="0.001 0.001 0.001"/>
      </geometry>
      <material name="silver"/>
    </visual>
    <collision>
      <origin rpy="0 0 0" xyz="3.9e-05 -0.0513 -1.012779"/>
      <geometry>
        <mesh filename="meshes_7sky/J7_1.stl" scale="0.001 0.001 0.001"/>
      </geometry>
    </collision>
  </link>
  <link name="cam_1">
    <inertial>
      <origin rpy="0 0 0" xyz="2.9606115520747103e-05 -0.007206203502401615 0.0099796216106387"/>
      <mass value="0.3273893989685979"/>
      <inertia ixx="2.4e-05" ixy="0.0" ixz="-0.0" iyy="0.00025" iyz="0.0" izz="0.000252"/>
    </inertial>
    <visual>
      <origin rpy="0 0 0" xyz="2.8e-05 -0.086775 -1.022779"/>
      <geometry>
        <mesh filename="meshes_7sky/cam_1.stl" scale="0.001 0.001 0.001"/>
      </geometry>
      <material name="silver"/>
    </visual>
    <collision>
      <origin rpy="0 0 0" xyz="2.8e-05 -0.086775 -1.022779"/>
      <geometry>
        <mesh filename="meshes_7sky/cam_1.stl" scale="0.001 0.001 0.001"/>
      </geometry>
    </collision>
  </link>
  <joint name="Sztywne 1" type="fixed">
    <origin rpy="0 0 0" xyz="0.0 0.0 0.012"/>
    <parent link="base_link"/>
    <child link="cover1_1"/>
  </joint>
  <joint name="Sztywne 2" type="fixed">
    <origin rpy="0 0 0" xyz="-0.0 0.048 0.124"/>
    <parent link="cover1_1"/>
    <child link="J1_1"/>
  </joint>
  <joint name="Obr�t 3" type="continuous">
    <origin rpy="0 0 0" xyz="0.0 -0.048 0.036"/>
    <parent link="J1_1"/>
    <child link="L1_1"/>
    <axis xyz="0.0 0.0 -1.0"/>
  </joint>
  <joint name="Sztywne 4" type="fixed">
    <origin rpy="0 0 0" xyz="0.0 0.0186 0.01846"/>
    <parent link="L1_1"/>
    <child link="J2_1"/>
  </joint>
  <joint name="Obr�t 5" type="continuous">
    <origin rpy="0 0 0" xyz="0.0 0.036 0.048"/>
    <parent link="J2_1"/>
    <child link="L2_1"/>
    <axis xyz="-0.0 -1.0 -0.0"/>
  </joint>
  <joint name="Sztywne 6" type="fixed">
    <origin rpy="0 0 0" xyz="-1.4e-05 -0.0055 0.19"/>
    <parent link="L2_1"/>
    <child link="J3_1"/>
  </joint>
  <joint name="Obr�t 7" type="continuous">
    <origin rpy="0 0 0" xyz="-5.6e-05 -0.048 0.036"/>
    <parent link="J3_1"/>
    <child link="L3_1"/>
    <axis xyz="0.0 0.0 -1.0"/>
  </joint>
  <joint name="Sztywne 8" type="fixed">
    <origin rpy="0 0 0" xyz="2.2e-05 0.0186 0.018459"/>
    <parent link="L3_1"/>
    <child link="J4_1"/>
  </joint>
  <joint name="Obr�t 9" type="continuous">
    <origin rpy="0 0 0" xyz="4.1e-05 0.036 0.048"/>
    <parent link="J4_1"/>
    <child link="L4_1"/>
    <axis xyz="-0.001154 -0.999999 -0.0"/>
  </joint>
  <joint name="Sztywne 10" type="fixed">
    <origin rpy="0 0 0" xyz="-2.1e-05 -0.0055 0.19"/>
    <parent link="L4_1"/>
    <child link="J5_1"/>
  </joint>
  <joint name="Obr�t 11" type="continuous">
    <origin rpy="0 0 0" xyz="-0.00011 -0.048 0.0354"/>
    <parent link="J5_1"/>
    <child link="L5_1"/>
    <axis xyz="0.0 -0.0 1.0"/>
  </joint>
  <joint name="Sztywne 12" type="fixed">
    <origin rpy="0 0 0" xyz="4.3e-05 0.0186 0.01846"/>
    <parent link="L5_1"/>
    <child link="J6_1"/>
  </joint>
  <joint name="Sztywne 13" type="fixed">
    <origin rpy="0 0 0" xyz="8.3e-05 0.036 0.048"/>
    <parent link="J6_1"/>
    <child link="L6_1"/>
  </joint>
  <joint name="Sztywne 14" type="fixed">
    <origin rpy="0 0 0" xyz="-2.7e-05 -0.0055 0.19"/>
    <parent link="L6_1"/>
    <child link="J7_1"/>
  </joint>
  <joint name="Sztywne 16" type="fixed">
    <origin rpy="0 0 0" xyz="-1.6e-05 0.029975 0.2"/>
    <parent link="L6_1"/>
    <child link="cam_1"/>
  </joint>
</robot>
